Workbook

Sheet Sprint Overview
A1: Sprint | B1: Week | C1: Sprint Goal | D1: Key Epics / Work Streams
A2: Sprint 1 | B2: Week 1 | C2: Lay the foundation: accounts, authentication, patient and provider profiles, design system. Front-end also starts building the Search Results and Provider Details pages against mock data. | D2: E1 (partial), E2 (partial), E3 (partial), E4/E5 (UI shell only), E10 (partial), Design, Analytics, QA, PM
A3: Sprint 2 | B3: Week 2 | C3: Search, provider availability, and license verification; wire the Sprint 1 mock UI to real endpoints | D3: E3 (license submission), E9 (license review), E6, E4, E5, E10, Design, Analytics, QA, PM
A4: Sprint 3 | B4: Week 3 | C4: End-to-end integration of pages 1-3, account management, password reset, onboarding for Vanya | D4: E1 (password reset), E9 (account management), E10 (final), Integration, Design, Analytics, QA, PM
A5: Sprint 4 | B5: Week 4 | C5: Appointment booking, appointment management, stabilization and release prep | D5: E7, E8, E2 (remainder), E6 (remainder), Support, Design, Analytics, QA, PM

Sheet Sprint Backlog
A1: # | B1: Sprint | C1: Epic | D1: Label | E1: Type | F1: Summary (issue) | G1: Assignee | H1: Role | I1: Note
A2: 1 | B2: Sprint 1 | C2: Design | D2: design | E2: Task | F2: Wireframes for the 4 site pages | G2: Illia | H2: Designer (UI/UX)
A3: 2 | B3: Sprint 1 | C3: Design | D3: design | E3: Task | F3: UI kit (colors, typography, base components) | G3: Illia | H3: Designer (UI/UX)
A4: 3 | B4: Sprint 1 | C4: E1 | D4: E1-S1 | E4: Story | F4: As a user, I want to register with email and password, so that I can get access to the platform.
A5: 4 | B5: Sprint 1 | C5: E1 | D5: E1-S1 | E5: Task | F5: Build the registration API (backend) | G5: Marika | H5: Backend Developer
A6: 5 | B6: Sprint 1 | C6: E1 | D6: E1-S1 | E6: Sub-task | F6: Validate email format and minimum password requirements | G6: Marika | H6: Backend Developer
A7: 6 | B7: Sprint 1 | C7: E1 | D7: E1-S1 | E7: Sub-task | F7: Hash the password before storing it in the database | G7: Marika | H7: Backend Developer
A8: 7 | B8: Sprint 1 | C8: E1 | D8: E1-S1 | E8: Sub-task | F8: Check for duplicate email addresses | G8: Marika | H8: Backend Developer
A9: 8 | B9: Sprint 1 | C9: E1 | D9: E1-S1 | E9: Task | F9: Build the registration form (frontend) | G9: Yana | H9: Front-end Developer
A10: 9 | B10: Sprint 1 | C10: E1 | D10: E1-S1 | E10: Sub-task | F10: Client-side field validation | G10: Yana | H10: Front-end Developer
A11: 10 | B11: Sprint 1 | C11: E1 | D11: E1-S1 | E11: Sub-task | F11: Handle and display API errors | G11: Yana | H11: Front-end Developer
A12: 11 | B12: Sprint 1 | C12: E1 | D12: E1-S2 | E12: Story | F12: As a user, I want to choose my role during registration (patient / provider), so that the system shows me the right functionality.
A13: 12 | B13: Sprint 1 | C13: E1 | D13: E1-S2 | E13: Task | F13: Add a "role" field to the user model | G13: Marika | H13: Backend Developer
A14: 13 | B14: Sprint 1 | C14: E1 | D14: E1-S2 | E14: Task | F14: Implement a role switch on the registration form | G14: Yana | H14: Front-end Developer
A15: 14 | B15: Sprint 1 | C15: E1 | D15: E1-S3 | E15: Story | F15: As a user, I want to log in, so that I can reach my personal cabinet.
A16: 15 | B16: Sprint 1 | C16: E1 | D16: E1-S3 | E16: Task | F16: Login API that issues a token/session | G16: Marika | H16: Backend Developer
A17: 16 | B17: Sprint 1 | C17: E1 | D17: E1-S3 | E17: Sub-task | F17: Basic rate limiting on failed login attempts | G17: Marika | H17: Backend Developer
A18: 17 | B18: Sprint 1 | C18: E1 | D18: E1-S3 | E18: Task | F18: Login form (frontend) | G18: Yaroslav | H18: Front-end Developer
A19: 18 | B19: Sprint 1 | C19: E1 | D19: E1-S4 | E19: Story | F19: As a user, I want to log out, so that I can protect my account on a shared device.
A20: 19 | B20: Sprint 1 | C20: E1 | D20: E1-S4 | E20: Task | F20: Implement logout (invalidate token/session) | G20: Marika | H20: Backend Developer
A21: 20 | B21: Sprint 1 | C21: E1 | D21: E1-S5 | E21: Story | F21: As a user, I want to reset my password if I forget it.
A22: 21 | B22: Sprint 1 | C22: E1 | D22: E1-S5 | E22: Task | F22: New-password form (frontend) | G22: Yaroslav | H22: Front-end Developer | I22: Backend tasks for this story moved to Sprint 3 - see rebalancing note
A23: 22 | B23: Sprint 1 | C23: E2 | D23: E2-S1 | E23: Story | F23: As a patient, I want to create and edit my profile, so that the provider and the system see up-to-date information about me.
A24: 23 | B24: Sprint 1 | C24: E2 | D24: E2-S1 | E24: Task | F24: Patient profile CRUD API | G24: Marika | H24: Backend Developer
A25: 24 | B25: Sprint 1 | C25: E2 | D25: E2-S1 | E25: Task | F25: Profile create/edit form (UI) | G25: Yana | H25: Front-end Developer
A26: 25 | B26: Sprint 1 | C26: E2 | D26: E2-S2 | E26: Story | F26: As a patient, I want to specify my location, so that I get relevant search results.
A27: 26 | B27: Sprint 1 | C27: E2 | D27: E2-S2 | E27: Task | F27: Text field for location + save it to the profile | G27: Yaroslav | H27: Front-end Developer
A28: 27 | B28: Sprint 1 | C28: E2 | D28: E2-S3 | E28: Story | F28: As a patient, I want to specify the language(s) I speak, so that I can find a provider I can communicate with.
A29: 28 | B29: Sprint 1 | C29: E2 | D29: E2-S3 | E29: Task | F29: Multi-select language field in the profile | G29: Yaroslav | H29: Front-end Developer
A30: 29 | B30: Sprint 1 | C30: E2 | D30: E2-S4 | E30: Story | F30: As a patient, I want to optionally specify my pregnancy week, giving explicit consent to its processing.
A31: 30 | B31: Sprint 1 | C31: E2 | D31: E2-S4 | E31: Task | F31: "Pregnancy week" field + a separate explicit-consent checkbox | G31: Yaroslav | H31: Front-end Developer
A32: 31 | B32: Sprint 1 | C32: E2 | D32: E2-S4 | E32: Sub-task | F32: Explanatory text on why this data is collected and how it is used | G32: Anna | H32: PM
A33: 32 | B33: Sprint 1 | C33: E3 | D33: E3-S1 | E33: Story | F33: As a provider, I want to create and edit a profile (name, specialization, address, languages, description, contacts).
A34: 33 | B34: Sprint 1 | C34: E3 | D34: E3-S1 | E34: Task | F34: Provider profile CRUD API | G34: Marika | H34: Backend Developer
A35: 34 | B35: Sprint 1 | C35: E3 | D35: E3-S1 | E35: Task | F35: Provider profile form (UI) | G35: Yana | H35: Front-end Developer
A36: 35 | B36: Sprint 1 | C36: E3 | D36: E3-S2 | E36: Story | F36: As a provider, I want to list the services I offer, so that patients can select them when booking.
A37: 36 | B37: Sprint 1 | C37: E3 | D37: E3-S2 | E37: Task | F37: "Service" model (name, duration) | G37: Marika | H37: Backend Developer
A38: 37 | B38: Sprint 1 | C38: E3 | D38: E3-S2 | E38: Task | F38: UI to manage the list of services (add/edit/remove) | G38: Yana | H38: Front-end Developer
A39: 38 | B39: Sprint 1 | C39: E4 | D39: E4-S1 | E39: Task | F39: Search results page UI with a filter panel | G39: Yaroslav | H39: Front-end Developer | I39: Built against mock data and Sprint 1 wireframes; wired to the live endpoint in Sprint 2
A40: 39 | B40: Sprint 1 | C40: E5 | D40: E5-S1 | E40: Task | F40: Provider profile page UI | G40: Yaroslav | H40: Front-end Developer | I40: Built against mock data and Sprint 1 wireframes; wired to the live endpoint in Sprint 2
...

Sheet Team Workload
A1: Assignee | B1: Role | C1: Sprint 1 | D1: Sprint 2 | E1: Sprint 3 | F1: Sprint 4 | G1: Total
A2: Anna | B2: PM | C2: =COUNTIFS('Sprint Backlog'!$B$2:$B$142,"Sprint 1",'Sprint Backlog'!$G$2:$G$142,"Anna") -> 3 | D2: =COUNTIFS('Sprint Backlog'!$B$2:$B$142,"Sprint 2",'Sprint Backlog'!$G$2:$G$142,"Anna") -> 2 | E2: =COUNTIFS('Sprint Backlog'!$B$2:$B$142,"Sprint 3",'Sprint Backlog'!$G$2:$G$142,"Anna") -> 3 | F2: =COUNTIFS('Sprint Backlog'!$B$2:$B$142,"Sprint 4",'Sprint Backlog'!$G$2:$G$142,"Anna") -> 2 | G2: =SUM(C2:F2) -> 10
A3: Illia | B3: Designer (UI/UX) | C3: =COUNTIFS('Sprint Backlog'!$B$2:$B$142,"Sprint 1",'Sprint Backlog'!$G$2:$G$142,"Illia") -> 2 | D3: =COUNTIFS('Sprint Backlog'!$B$2:$B$142,"Sprint 2",'Sprint Backlog'!$G$2:$G$142,"Illia") -> 1 | E3: =COUNTIFS('Sprint Backlog'!$B$2:$B$142,"Sprint 3",'Sprint Backlog'!$G$2:$G$142,"Illia") -> 2 | F3: =COUNTIFS('Sprint Backlog'!$B$2:$B$142,"Sprint 4",'Sprint Backlog'!$G$2:$G$142,"Illia") -> 1 | G3: =SUM(C3:F3) -> 6
A4: Yana | B4: Front-end Developer | C4: =COUNTIFS('Sprint Backlog'!$B$2:$B$142,"Sprint 1",'Sprint Backlog'!$G$2:$G$142,"Yana") -> 7 | D4: =COUNTIFS('Sprint Backlog'!$B$2:$B$142,"Sprint 2",'Sprint Backlog'!$G$2:$G$142,"Yana") -> 2 | E4: =COUNTIFS('Sprint Backlog'!$B$2:$B$142,"Sprint 3",'Sprint Backlog'!$G$2:$G$142,"Yana") -> 3 | F4: =COUNTIFS('Sprint Backlog'!$B$2:$B$142,"Sprint 4",'Sprint Backlog'!$G$2:$G$142,"Yana") -> 3 | G4: =SUM(C4:F4) -> 15
A5: Yaroslav | B5: Front-end Developer | C5: =COUNTIFS('Sprint Backlog'!$B$2:$B$142,"Sprint 1",'Sprint Backlog'!$G$2:$G$142,"Yaroslav") -> 7 | D5: =COUNTIFS('Sprint Backlog'!$B$2:$B$142,"Sprint 2",'Sprint Backlog'!$G$2:$G$142,"Yaroslav") -> 3 | E5: =COUNTIFS('Sprint Backlog'!$B$2:$B$142,"Sprint 3",'Sprint Backlog'!$G$2:$G$142,"Yaroslav") -> 2 | F5: =COUNTIFS('Sprint Backlog'!$B$2:$B$142,"Sprint 4",'Sprint Backlog'!$G$2:$G$142,"Yaroslav") -> 2 | G5: =SUM(C5:F5) -> 14
A6: Marika | B6: Backend Developer | C6: =COUNTIFS('Sprint Backlog'!$B$2:$B$142,"Sprint 1",'Sprint Backlog'!$G$2:$G$142,"Marika") -> 14 | D6: =COUNTIFS('Sprint Backlog'!$B$2:$B$142,"Sprint 2",'Sprint Backlog'!$G$2:$G$142,"Marika") -> 12 | E6: =COUNTIFS('Sprint Backlog'!$B$2:$B$142,"Sprint 3",'Sprint Backlog'!$G$2:$G$142,"Marika") -> 5 | F6: =COUNTIFS('Sprint Backlog'!$B$2:$B$142,"Sprint 4",'Sprint Backlog'!$G$2:$G$142,"Marika") -> 3 | G6: =SUM(C6:F6) -> 34
A7: Vanya | B7: Backend Developer | C7: =COUNTIFS('Sprint Backlog'!$B$2:$B$142,"Sprint 1",'Sprint Backlog'!$G$2:$G$142,"Vanya") -> 0 | D7: =COUNTIFS('Sprint Backlog'!$B$2:$B$142,"Sprint 2",'Sprint Backlog'!$G$2:$G$142,"Vanya") -> 0 | E7: =COUNTIFS('Sprint Backlog'!$B$2:$B$142,"Sprint 3",'Sprint Backlog'!$G$2:$G$142,"Vanya") -> 0 | F7: =COUNTIFS('Sprint Backlog'!$B$2:$B$142,"Sprint 4",'Sprint Backlog'!$G$2:$G$142,"Vanya") -> 6 | G7: =SUM(C7:F7) -> 6
A8: Iryna | B8: QA | C8: =COUNTIFS('Sprint Backlog'!$B$2:$B$142,"Sprint 1",'Sprint Backlog'!$G$2:$G$142,"Iryna") -> 3 | D8: =COUNTIFS('Sprint Backlog'!$B$2:$B$142,"Sprint 2",'Sprint Backlog'!$G$2:$G$142,"Iryna") -> 2 | E8: =COUNTIFS('Sprint Backlog'!$B$2:$B$142,"Sprint 3",'Sprint Backlog'!$G$2:$G$142,"Iryna") -> 3 | F8: =COUNTIFS('Sprint Backlog'!$B$2:$B$142,"Sprint 4",'Sprint Backlog'!$G$2:$G$142,"Iryna") -> 3 | G8: =SUM(C8:F8) -> 11
A9: Oksana | B9: Data Analyst | C9: =COUNTIFS('Sprint Backlog'!$B$2:$B$142,"Sprint 1",'Sprint Backlog'!$G$2:$G$142,"Oksana") -> 1 | D9: =COUNTIFS('Sprint Backlog'!$B$2:$B$142,"Sprint 2",'Sprint Backlog'!$G$2:$G$142,"Oksana") -> 1 | E9: =COUNTIFS('Sprint Backlog'!$B$2:$B$142,"Sprint 3",'Sprint Backlog'!$G$2:$G$142,"Oksana") -> 1 | F9: =COUNTIFS('Sprint Backlog'!$B$2:$B$142,"Sprint 4",'Sprint Backlog'!$G$2:$G$142,"Oksana") -> 1 | G9: =SUM(C9:F9) -> 4
A10: Total | C10: =SUM(C2:C9) -> 37 | D10: =SUM(D2:D9) -> 23 | E10: =SUM(E2:E9) -> 19 | F10: =SUM(F2:F9) -> 21 | G10: =SUM(G2:G9) -> 100

Sheet Legend & Labels
A1: LABELING SCHEME (for free Jira, where Task cannot have a Story as Parent)
A3: Every User Story gets a label in the form "{Epic}-S{n}" (e.g. E1-S1, E2-S3). Apply the same label to the Story issue AND to every Task/Sub-task that implements it. Set the Epic Link/Parent on both the Story and its Tasks to the SAME Epic (E1-E11). This lets you filter/group by label in the Backlog to see which Tasks belong to which Story, even though Jira Free has no direct Story-to-Task parent link.
A5: For E4 (Search & Filtering) and E6 (Availability Management), several User Stories share the same implementation Tasks (they will be delivered together as one feature slice), so all of them carry one combined label: E4-S1 and E6-S1 respectively.
A7: Work streams that are not part of the original E1-E11 backlog (Design, Analytics, QA, PM, Integration, Support) use a simple domain label instead: design, analytics, qa, pm, integration, support. In Jira these can be modeled as small standalone Epics, or simply as Tasks with that label and no Epic Link.
A9: E11 (Post-MVP / Future backlog) items use a single shared label "e11-post-mvp" and are not assigned to any sprint.
A11: WORK-ASSIGNMENT ASSUMPTIONS
A13: 1. Backend: Marika owns all backend work except the Appointment Booking domain (Epic E7) and the closely related parts of E8 and E2-S5 (viewing appointments) - that whole block is handed to Vanya, who joins the team in Sprint 4. In Sprint 4, Marika takes a supporting role: code review of the integration, final testing of already-built modules (E9, E10), and the final infrastructure audit.
A15: 2. Frontend work is distributed between Yana and Yaroslav to balance workload as evenly as possible, both in total and per sprint, while keeping closely related tasks within the same feature together where practical (e.g. a Task and its own Sub-tasks stay with one owner). It is not a strict split by page or by "manage vs. discover" - either developer may pick up a task on any of the 4 pages if that keeps the load balanced.
A17: 3. Story issues in the table have no personal assignee - they are the grouping level; the actual work and ownership are recorded at the Task/Sub-task level.
A19: 4. All Epic names and User Story / Task / Sub-task wording for E1-E11 are quoted exactly from the source document "Backlog_and_Sitemap_EN.docx".
A21: SPRINT 1 REBALANCING (fix applied after review)
A23: An earlier version of this plan left Yaroslav unassigned in Sprint 1, overloaded Marika with 20 items, and gave Yana far more front-end work overall than Yaroslav (20 vs 9). This has been corrected in two ways. First, Yaroslav now starts building the Search & Results and Provider Details page UI in Sprint 1 against mock data and the Sprint 1 wireframes (labels E4-S1/E5-S1), instead of waiting idle until their backend endpoints exist in Sprint 2; these are then wired to the live endpoints early in Sprint 2. Second, several Sprint 1 front-end tasks that do not need to stay with Yana for feature-cohesion reasons (the login form, the new-password form, and the patient's location/language/pregnancy-week fields) were reassigned to Yaroslav, bringing the front-end split to roughly 15 (Yana) / 14 (Yaroslav) overall, and 7/7 in Sprint 1 specifically. On the backend side, two lower-priority items have been pushed out of Sprint 1: the license-submission story E3-S3 now ships in Sprint 2 together with the E9-S1 license-review queue it depends on, and the password-reset story E1-S5's backend tasks move to Sprint 3, since password reset is not required for the core acceptance-criterion demo flow. Marika's Sprint 1 load drops from 20 to 14 items. Full parity across all sprints is not achievable while Marika remains the only backend developer through Sprint 3 - the goal here is a realistic, reduced front-loading rather than an artificial even split.
